<mujoco model="onshape">
  <compiler angle="radian"/>
  
  <asset>
    <mesh name="base_link" file="base_link.stl"/>
    <mesh name="link_0_0" file="link_0_0.stl"/>
    <mesh name="link_0_1" file="link_0_1.stl"/>
    <mesh name="link_0_2" file="link_0_2.stl"/>
    <mesh name="link_1_0" file="link_1_0.stl"/>
    <mesh name="link_1_1" file="link_1_1.stl"/>
    <mesh name="link_1_2" file="link_1_2.stl"/>
    <mesh name="link_2_0" file="link_2_0.stl"/>
    <mesh name="link_2_1" file="link_2_1.stl"/>
    <mesh name="link_2_2" file="link_2_2.stl"/>
  </asset>

  <worldbody>
    <geom pos="0.0225 0 0.004" quat="0.707107 0 0 0.707107" type="mesh" rgba="0.615686 0.811765 0.929412 1" mesh="base_link"/>
    
    <!-- Link 0 -->
    <body name="link_0_0" pos="0.0115 0.0205 0.032" quat="0.707107 0 0.707107 0">
      <joint name="base_l00" pos="0 0 0" axis="0 0 1" range="0 1.48353" damping="5"/>
      <geom quat="0.5 -0.5 -0.5 -0.5" type="mesh" rgba="0.615686 0.811765 0.929412 1" mesh="link_0_0"/>
      
      <body name="link_0_1" pos="0 0 0.0215" quat="0 -0.707107 0 -0.707107">
        <joint name="l00_l01" pos="0 0 0" axis="0 0 1" range="0 1.0472" damping="5"/>
        <geom quat="0 -1 0 0" type="mesh" rgba="0.615686 0.811765 0.929412 1" mesh="link_0_1"/>
        
        <body name="link_0_2" pos="0.0155 -0.0711023 -0.0251023" quat="0.299418 -0.640585 0.299418 -0.640585">
          <joint name="l01_l02" pos="0 0 0" axis="0 0 1" range="0 0.785398" damping="100"/>
          <geom pos="0 -0.0045 -0.007" quat="0.5 -0.5 -0.5 -0.5" type="mesh" rgba="0.615686 0.811765 0.929412 1" mesh="link_0_2"/>
        </body>
      </body>
    </body>

    <!-- Link 1 -->
    <body name="link_1_0" pos="0.0125 0.0335 0.107" quat="0.5 0.5 -0.5 -0.5">
      <joint name="base_l10" pos="0 0 0" axis="0 0 1" range="-0.349066 0.349066" damping="20"/>
      <geom quat="0.707107 0.707107 0 0" type="mesh" rgba="0.615686 0.811765 0.929412 1" mesh="link_1_0"/>
      
      <body name="link_1_1" pos="0.0041 0 -0.003" quat="0.707107 0 -0.707107 0">
        <joint name="l10_l11" pos="0 0 0" axis="0 0 1" range="0 1.5708" damping="5"/>
        <geom pos="0 0 0.0082" quat="0.5 -0.5 -0.5 -0.5" type="mesh" rgba="0.615686 0.811765 0.929412 1" mesh="link_1_1"/>
        
        <body name="link_1_2" pos="0 0.048 0.0122" quat="1 0 0 0">
          <joint name="l11_l12" pos="0 0 0" axis="0 0 1" range="0 1.8326" damping="150"/>
          <geom pos="0 -0.0045 -0.0081" quat="0.5 -0.5 -0.5 -0.5" type="mesh" rgba="0.615686 0.811765 0.929412 1" mesh="link_1_2"/>
        </body>
      </body>
    </body>

    <!-- Link 2 -->
    <body name="link_2_0" pos="0.0125 0.0085 0.107" quat="0.5 -0.5 0.5 -0.5">
      <joint name="base_l20" pos="0 0 0" axis="0 0 1" range="-0.349066 0.349066" damping="20"/>
      <geom quat="0.707107 -0.707107 0 0" type="mesh" rgba="0.615686 0.811765 0.929412 1" mesh="link_2_0"/>
      
      <body name="link_2_1" pos="-0.0041 0 0.003" quat="0 -0.707107 0 0.707107">
        <joint name="l20_l21" pos="0 0 0" axis="0 0 1" range="0 1.5708" damping="5"/>
        <geom quat="0.5 -0.5 -0.5 -0.5" type="mesh" rgba="0.615686 0.811765 0.929412 1" mesh="link_2_1"/>
        
        <body name="link_2_2" pos="0 0.055 0.004" quat="1 0 0 0">
          <joint name="l21_l22" pos="0 0 0" axis="0 0 1" range="0 1.8326" damping="150"/>
          <geom pos="0 -0.0045 -0.0081" quat="0.5 -0.5 -0.5 -0.5" type="mesh" rgba="0.615686 0.811765 0.929412 1" mesh="link_2_2"/>
        </body>
      </body>
    </body>

  </worldbody>

  <!-- Actuator Section: Adding position actuators for each joint -->
  <actuator>
    <!-- Actuators for link_0 -->
    <position joint="base_l00" ctrlrange="0 1.48353" kp="40"/>
    <position joint="l00_l01" ctrlrange="0 1.0472" kp="40"/>
    <position joint="l01_l02" ctrlrange="0 0.785398" kp="200"/>

    <!-- Actuators for link_1 -->
    <position joint="base_l10" ctrlrange="-0.349066 0.349066" kp="500"/>
    <position joint="l10_l11" ctrlrange="0 1.5708" kp="40"/>
    <position joint="l11_l12" ctrlrange="0 1.8326" kp="200"/>

    <!-- Actuators for link_2 -->
    <position joint="base_l20" ctrlrange="-0.349066 0.349066" kp="500"/>
    <position joint="l20_l21" ctrlrange="0 1.5708" kp="40"/>
    <position joint="l21_l22" ctrlrange="0 1.8326" kp="200"/>
  </actuator>
</mujoco>