<robot name="onshape">
<link name="base_link">
<visual>
<origin xyz="0.022499999999999999167 0 0.004000000000000001818" rpy="-6.1232339957367660359e-17 -0 1.570796326794896558" />
<geometry>
<mesh filename="meshes/base_link.stl"/>
</geometry>
<material name="base_link_material">
<color rgba="0.61568627450980395466 0.81176470588235294379 0.92941176470588238168 1.0"/>
</material>
</visual>
<collision>
<origin xyz="0.022499999999999999167 0 0.004000000000000001818" rpy="-6.1232339957367660359e-17 -0 1.570796326794896558" />
<geometry>
<mesh filename="meshes/base_link.stl"/>
</geometry>
</collision>
<inertial>
<origin xyz="0.00039299999999997041293 0.0012500000000000017607 0.050382000000000058682" rpy="0 0 0"/>
<mass value="0.69999999999999895639" />
<inertia ixx="0.00091975000000000010306" ixy="1.4059670824682581796e-05"  ixz="-5.0134299895249528e-05" iyy="0.00064095334999999999809" iyz="-1.2660829247592519746e-05" izz="0.00057912900000000005866" />
</inertial>
</link>

<link name="back_hand">
<inertial>
<origin xyz="0 0 0" rpy="0 0 0" />
<mass value="1e-9" />
<inertia ixx="0" ixy="0" ixz="0" iyy="0" iyz="0" izz="0" />
</inertial>
</link>
<joint name="back_hand_frame" type="fixed">
<origin xyz="-0.012000000000000010658 0.0087950000000000007339 0.08300000000000000433" rpy="-3.141592653589793116 -1.570796326794896558 0" />
<parent link="base_link" />
<child link="back_hand" />
<axis xyz="0 0 0"/>
</joint>

<link name="link_0_0">
<visual>
<origin xyz="0 0 0" rpy="-1.570796326794896558 -1.570796326794896558 0" />
<geometry>
<mesh filename="meshes/link_0_0.stl"/>
</geometry>
<material name="link_0_0_material">
<color rgba="0.61568627450980395466 0.81176470588235294379 0.92941176470588238168 1.0"/>
</material>
</visual>
<collision>
<origin xyz="0 0 0" rpy="-1.570796326794896558 -1.570796326794896558 0" />
<geometry>
<mesh filename="meshes/link_0_0.stl"/>
</geometry>
</collision>
<inertial>
<origin xyz="0.013948999999999999594 9.5512043114350516298e-19 0.019587000000000000244" rpy="0 0 0"/>
<mass value="0.12800000000000003042" />
<inertia ixx="3.19146156500755494e-05" ixy="-2.0489391457552031912e-38"  ixz="-8.0439952883636156129e-07" iyy="3.1474733414388381375e-05" iyz="-7.6025014959503108629e-38" izz="2.8490043198646855527e-05" />
</inertial>
</link>

<link name="link_0_1">
<visual>
<origin xyz="6.9388939039072283776e-18 4.8572257327350598644e-17 0" rpy="-3.141592653589793116 -7.8475303096459979674e-32 -2.4179613096907262284e-32" />
<geometry>
<mesh filename="meshes/link_0_1.stl"/>
</geometry>
<material name="link_0_1_material">
<color rgba="0.61568627450980395466 0.81176470588235294379 0.92941176470588238168 1.0"/>
</material>
</visual>
<collision>
<origin xyz="6.9388939039072283776e-18 4.8572257327350598644e-17 0" rpy="-3.141592653589793116 -7.8475303096459979674e-32 -2.4179613096907262284e-32" />
<geometry>
<mesh filename="meshes/link_0_1.stl"/>
</geometry>
</collision>
<inertial>
<origin xyz="0.0084530000000000108523 -0.039625999999999959866 0.0024310000000000000012" rpy="0 0 0"/>
<mass value="0.045999999999999985345" />
<inertia ixx="2.3368923926605413162e-05" ixy="6.0418261424786376445e-07"  ixz="-5.4358686285291777287e-08" iyy="7.2542608497344604804e-06" iyz="-3.6081252959038368649e-06" izz="1.9531928502098601814e-05" />
</inertial>
</link>

<link name="link_0_2">
<visual>
<origin xyz="1.3877787807814456755e-17 -0.004499999999999990119 -0.0069999999999999992784" rpy="-1.570796326794896558 -1.570796326794896558 0" />
<geometry>
<mesh filename="meshes/link_0_2.stl"/>
</geometry>
<material name="link_0_2_material">
<color rgba="0.61568627450980395466 0.81176470588235294379 0.92941176470588238168 1.0"/>
</material>
</visual>
<collision>
<origin xyz="1.3877787807814456755e-17 -0.004499999999999990119 -0.0069999999999999992784" rpy="-1.570796326794896558 -1.570796326794896558 0" />
<geometry>
<mesh filename="meshes/link_0_2.stl"/>
</geometry>
</collision>
<inertial>
<origin xyz="0.0001370000000000143076 0.0094880000000000103144 -0.0070000001041999994691" rpy="0 0 0"/>
<mass value="0.0060000000000000018596" />
<inertia ixx="5.5804280736782390273e-07" ixy="9.6190184039645028517e-08"  ixz="-1.2012932679583274374e-37" iyy="2.4377397642684847816e-07" iyz="5.6783030342953052041e-38" izz="5.2560794285760837064e-07" />
</inertial>
</link>

<link name="thumb_tip">
<inertial>
<origin xyz="0 0 0" rpy="0 0 0" />
<mass value="1e-9" />
<inertia ixx="0" ixy="0" ixz="0" iyy="0" iyz="0" izz="0" />
</inertial>
</link>
<joint name="thumb_tip_frame" type="fixed">
<origin xyz="6.9388939039072283776e-18 0.025500000000000022649 -0.0069999999999999992784" rpy="-1.570796326794896558 -1.2246467991473490164e-16 1.5707963267948903408" />
<parent link="link_0_2" />
<child link="thumb_tip" />
<axis xyz="0 0 0"/>
</joint>

<joint name="l01_l02" type="revolute">
<origin xyz="0.015499999999999819478 -0.071102290732122458428 -0.025102290732122459205" rpy="-1.570796326794896558 -0.69631528840256062818 -1.5707963267949023312" />
<parent link="link_0_1" />
<child link="link_0_2" />
<axis xyz="0 0 1"/>
<limit effort="0.6" velocity="2" upper="0.785398" lower="0" />
<joint_properties friction="0.0"/>
</joint>

<joint name="l00_l01" type="revolute">
<origin xyz="0 -3.8163916471489756077e-17 0.021500000000000005218" rpy="-3.1415926535897926719 -1.5707963267948934494 0" />
<parent link="link_0_0" />
<child link="link_0_1" />
<axis xyz="0 0 1"/>
<limit effort="1.2" velocity="2" upper="1.0472" lower="0" />
<joint_properties friction="0.0"/>
</joint>

<joint name="base_l00" type="revolute">
<origin xyz="0.011499999999999996336 0.020499999999999997391 0.032000000000000000666" rpy="-1.6616426800486583493e-15 1.570796326794896558 0" />
<parent link="base_link" />
<child link="link_0_0" />
<axis xyz="0 0 1"/>
<limit effort="1.2" velocity="2" upper="1.48353" lower="0" />
<joint_properties friction="0.0"/>
</joint>

<link name="link_1_0">
<visual>
<origin xyz="0 0 0" rpy="1.570796326794896558 4.7158863341051553336e-33 -2.4651903288156618919e-32" />
<geometry>
<mesh filename="meshes/link_1_0.stl"/>
</geometry>
<material name="link_1_0_material">
<color rgba="0.61568627450980395466 0.81176470588235294379 0.92941176470588238168 1.0"/>
</material>
</visual>
<collision>
<origin xyz="0 0 0" rpy="1.570796326794896558 4.7158863341051553336e-33 -2.4651903288156618919e-32" />
<geometry>
<mesh filename="meshes/link_1_0.stl"/>
</geometry>
</collision>
<inertial>
<origin xyz="0.000819146638064082778 -1.2832181956198874593e-08 -0.0027528628879477708841" rpy="0 0 0"/>
<mass value="1.0000000000000000818e-05" />
<inertia ixx="4.6927765119457290201e-11" ixy="-6.3603315141571130446e-16"  ixz="3.7052763596674654562e-12" iyy="5.9232011659831275745e-11" iyz="1.0205067640164029442e-15" izz="5.767071614087058313e-11" />
</inertial>
</link>

<link name="link_1_1">
<visual>
<origin xyz="1.7347234759768070944e-18 1.3877787807814456755e-17 0.0081999999999999989564" rpy="-1.570796326794896558 -1.570796326794896558 0" />
<geometry>
<mesh filename="meshes/link_1_1.stl"/>
</geometry>
<material name="link_1_1_material">
<color rgba="0.61568627450980395466 0.81176470588235294379 0.92941176470588238168 1.0"/>
</material>
</visual>
<collision>
<origin xyz="1.7347234759768070944e-18 1.3877787807814456755e-17 0.0081999999999999989564" rpy="-1.570796326794896558 -1.570796326794896558 0" />
<geometry>
<mesh filename="meshes/link_1_1.stl"/>
</geometry>
</collision>
<inertial>
<origin xyz="0.0087559999999999964249 0.022004000000000013132 0.0065050000000000003653" rpy="0 0 0"/>
<mass value="0.029000000000000018818" />
<inertia ixx="5.27762124602104313e-06" ixy="-1.0393620152342419468e-07"  ixz="1.1946977010413742665e-08" iyy="3.3556548243569315684e-06" iyz="1.0807160989266081313e-07" izz="6.248125894963155725e-06" />
</inertial>
</link>

<link name="link_1_2">
<visual>
<origin xyz="1.7347234759768070944e-18 -0.0045000000000000039968 -0.0081000000000000030309" rpy="-1.570796326794896558 -1.570796326794896558 0" />
<geometry>
<mesh filename="meshes/link_1_2.stl"/>
</geometry>
<material name="link_1_2_material">
<color rgba="0.61568627450980395466 0.81176470588235294379 0.92941176470588238168 1.0"/>
</material>
</visual>
<collision>
<origin xyz="1.7347234759768070944e-18 -0.0045000000000000039968 -0.0081000000000000030309" rpy="-1.570796326794896558 -1.570796326794896558 0" />
<geometry>
<mesh filename="meshes/link_1_2.stl"/>
</geometry>
</collision>
<inertial>
<origin xyz="-6.7999999999998278293e-05 0.01788200000000000206 -0.0081040543157719531486" rpy="0 0 0"/>
<mass value="0.0089999999999999958505" />
<inertia ixx="1.8182418038054153964e-06" ixy="1.957982473068381484e-07"  ixz="-1.5999225541587355522e-10" iyy="3.266295822213078712e-07" iyz="-3.5545707387990473304e-10" izz="1.7776359752083371624e-06" />
</inertial>
</link>

<link name="index_tip">
<inertial>
<origin xyz="0 0 0" rpy="0 0 0" />
<mass value="1e-9" />
<inertia ixx="0" ixy="0" ixz="0" iyy="0" iyz="0" izz="0" />
</inertial>
</link>
<joint name="index_tip_frame" type="fixed">
<origin xyz="0 0.04350000000000001088 -0.008100000000000585898" rpy="-1.57079632679489678 -2.3429107291650431014e-15 1.570796326794896558" />
<parent link="link_1_2" />
<child link="index_tip" />
<axis xyz="0 0 0"/>
</joint>

<joint name="l11_l12" type="revolute">
<origin xyz="3.4694469519536141888e-18 0.048000000000000000999 0.012200000000000016387" rpy="5.1000870193715387284e-16 3.6598190781807174636e-30 1.3877787807814518385e-16" />
<parent link="link_1_1" />
<child link="link_1_2" />
<axis xyz="0 0 1"/>
<limit effort="0.6" velocity="2" upper="1.8326" lower="0" />
<joint_properties friction="0.0"/>
</joint>

<joint name="l10_l11" type="revolute">
<origin xyz="0.004100000000000013356 -1.3877787807814456755e-17 -0.0030000000000000043993" rpy="-8.1445031776486881829e-16 -1.570796326794896558 0" />
<parent link="link_1_0" />
<child link="link_1_1" />
<axis xyz="0 0 1"/>
<limit effort="1.2" velocity="2" upper="1.5708" lower="0" />
<joint_properties friction="0.0"/>
</joint>

<joint name="base_l10" type="revolute">
<origin xyz="0.012499999999999990286 0.03349999999999999506 0.10700000000000002565" rpy="1.570796326794896558 3.8857805861880464124e-16 -1.570796326794896336" />
<parent link="base_link" />
<child link="link_1_0" />
<axis xyz="0 0 1"/>
<limit effort="1.2" velocity="2" upper="0.349066" lower="-0.349066"/>
<joint_properties friction="0.0"/>
</joint>

<link name="link_2_0">
<visual>
<origin xyz="0 0 0" rpy="-1.570796326794896558 1.2714758896382251659e-34 -2.7733391199176196284e-31" />
<geometry>
<mesh filename="meshes/link_2_0.stl"/>
</geometry>
<material name="link_2_0_material">
<color rgba="0.61568627450980395466 0.81176470588235294379 0.92941176470588238168 1.0"/>
</material>
</visual>
<collision>
<origin xyz="0 0 0" rpy="-1.570796326794896558 1.2714758896382251659e-34 -2.7733391199176196284e-31" />
<geometry>
<mesh filename="meshes/link_2_0.stl"/>
</geometry>
</collision>
<inertial>
<origin xyz="-0.00081914663806408288642 -1.2832181955765625513e-08 0.0027528628879477713177" rpy="0 0 0"/>
<mass value="1.0000000000000002512e-05" />
<inertia ixx="4.6927765119457296663e-11" ixy="6.3603315141545098036e-16"  ixz="3.7052763596674678796e-12" iyy="5.9232011659831314519e-11" iyz="-1.0205067640162692323e-15" izz="5.7670716140870589592e-11" />
</inertial>
</link>

<link name="link_2_1">
<visual>
<origin xyz="0 0 0" rpy="-1.570796326794896558 -1.570796326794896558 0" />
<geometry>
<mesh filename="meshes/link_2_1.stl"/>
</geometry>
<material name="link_2_1_material">
<color rgba="0.61568627450980395466 0.81176470588235294379 0.92941176470588238168 1.0"/>
</material>
</visual>
<collision>
<origin xyz="0 0 0" rpy="-1.570796326794896558 -1.570796326794896558 0" />
<geometry>
<mesh filename="meshes/link_2_1.stl"/>
</geometry>
</collision>
<inertial>
<origin xyz="0.0085439999999999995117 0.024626000000000002055 -0.0063329999999999983529" rpy="0 0 0"/>
<mass value="0.032000000000000000666" />
<inertia ixx="7.5121579278742119052e-06" ixy="-1.3758796641942274686e-07"  ixz="-2.4693395950631606476e-08" iyy="3.6903185474825162327e-06" iyz="-1.6799534293588041651e-07" izz="8.6555505371513904252e-06" />
</inertial>
</link>

<link name="link_2_2">
<visual>
<origin xyz="0 -0.0045000000000000039968 -0.0080999999999999978267" rpy="-1.570796326794896558 -1.570796326794896558 0" />
<geometry>
<mesh filename="meshes/link_2_2.stl"/>
</geometry>
<material name="link_2_2_material">
<color rgba="0.61568627450980395466 0.81176470588235294379 0.92941176470588238168 1.0"/>
</material>
</visual>
<collision>
<origin xyz="0 -0.0045000000000000039968 -0.0080999999999999978267" rpy="-1.570796326794896558 -1.570796326794896558 0" />
<geometry>
<mesh filename="meshes/link_2_2.stl"/>
</geometry>
</collision>
<inertial>
<origin xyz="-0.00026799999999999995484 0.021854999999999989019 -0.008102784667325156967" rpy="0 0 0"/>
<mass value="0.010000000000000001943" />
<inertia ixx="2.685189088507177864e-06" ixy="2.2862338094051682095e-07"  ixz="-1.1563037383062501311e-10" iyy="3.5734866796571522237e-07" iyz="-3.8132107836066552964e-10" izz="2.6340748543019151072e-06" />
</inertial>
</link>

<link name="middle_tip">
<inertial>
<origin xyz="0 0 0" rpy="0 0 0" />
<mass value="1e-9" />
<inertia ixx="0" ixy="0" ixz="0" iyy="0" iyz="0" izz="0" />
</inertial>
</link>
<joint name="middle_tip_frame" type="fixed">
<origin xyz="-1.7520707107365751654e-16 0.051500000000001072697 -0.008100000000000403752" rpy="-1.570796326794896336 -1.0522764630383045396e-15 1.570796326794896558" />
<parent link="link_2_2" />
<child link="middle_tip" />
<axis xyz="0 0 0"/>
</joint>

<joint name="l21_l22" type="revolute">
<origin xyz="-6.2450045135165055399e-17 0.055000000000000617839 0.0039999999999998005901" rpy="-1.3947176746853519178e-15 2.4109735503037200832e-18 1.2731915420014086542e-16" />
<parent link="link_2_1" />
<child link="link_2_2" />
<axis xyz="0 0 1"/>
<limit effort="0.6" velocity="2" upper="1.8326" lower="0" />
<joint_properties friction="0.0"/>
</joint>

<joint name="l20_l21" type="revolute">
<origin xyz="-0.0041000000000000966227 5.5511151231257827021e-16 0.00299999999999990552" rpy="-3.1415926535897917837 1.570796326794896558 0" />
<parent link="link_2_0" />
<child link="link_2_1" />
<axis xyz="0 0 1"/>
<limit effort="1.2" velocity="2" upper="1.5708" lower="0" />
<joint_properties friction="0.0"/>
</joint>

<joint name="base_l20" type="revolute">
<origin xyz="0.012500000000000085695 0.0084999999999998982619 0.10700000000000056688" rpy="-1.570796326794896558 1.4155343563970747863e-15 -1.570796326794896558" />
<parent link="base_link" />
<child link="link_2_0" />
<axis xyz="0 0 1"/>
<limit effort="1.2" velocity="2" upper="0.349066" lower="-0.349066" />
<joint_properties friction="0.0"/>
</joint>


</robot>
